Traceback (most recent call last):
  File "/home/peng/Documents/hemingway/.venv/lib/python3.10/site-packages/jupyter_cache/executors/utils.py", line 51, in single_nb_execution
    executenb(
  File "/home/peng/Documents/hemingway/.venv/lib/python3.10/site-packages/nbclient/client.py", line 1204, in execute
    return NotebookClient(nb=nb, resources=resources, km=km, **kwargs).execute()
  File "/home/peng/Documents/hemingway/.venv/lib/python3.10/site-packages/nbclient/util.py", line 84, in wrapped
    return just_run(coro(*args, **kwargs))
  File "/home/peng/Documents/hemingway/.venv/lib/python3.10/site-packages/nbclient/util.py", line 62, in just_run
    return loop.run_until_complete(coro)
  File "/home/peng/.pyenv/versions/3.10.6/lib/python3.10/asyncio/base_events.py", line 646, in run_until_complete
    return future.result()
  File "/home/peng/Documents/hemingway/.venv/lib/python3.10/site-packages/nbclient/client.py", line 663, in async_execute
    await self.async_execute_cell(
  File "/home/peng/Documents/hemingway/.venv/lib/python3.10/site-packages/nbclient/client.py", line 965, in async_execute_cell
    await self._check_raise_for_error(cell, cell_index, exec_reply)
  File "/home/peng/Documents/hemingway/.venv/lib/python3.10/site-packages/nbclient/client.py", line 862, in _check_raise_for_error
    raise CellExecutionError.from_cell_and_msg(cell, exec_reply_content)
nbclient.exceptions.CellExecutionError: An error occurred while executing the following cell:
------------------
import numpy as np
from scipy.stats import norm

def rungeIntegration(h, N, x0, y0, f):
    x = [x0,]
    y = [y0,]
    xt, yt = x0, y0
    for i in range(1, N):
        K1 = f(xt, yt)
        K2 = f(xt, yt + h/2 * K1)
        K3 = f(xt + h/2, yt + h/2 * K2)
        K4 = f(xt + h, yt + h * K3)
        xt += h
        yt = yt + h * (K1/6 + K2*2/6 + K3*2/6 + K4/6)
        x.append(xt)
        y.append(yt)
    return np.array(x), np.array(y)
------------------

[0;31m---------------------------------------------------------------------------[0m
[0;31mModuleNotFoundError[0m                       Traceback (most recent call last)
Cell [0;32mIn[6], line 2[0m
[1;32m      1[0m [38;5;28;01mimport[39;00m [38;5;21;01mnumpy[39;00m [38;5;28;01mas[39;00m [38;5;21;01mnp[39;00m
[0;32m----> 2[0m [38;5;28;01mfrom[39;00m [38;5;21;01mscipy[39;00m[38;5;21;01m.[39;00m[38;5;21;01mstats[39;00m [38;5;28;01mimport[39;00m norm
[1;32m      4[0m [38;5;28;01mdef[39;00m [38;5;21mrungeIntegration[39m(h, N, x0, y0, f):
[1;32m      5[0m     x [38;5;241m=[39m [x0,]

[0;31mModuleNotFoundError[0m: No module named 'scipy'
ModuleNotFoundError: No module named 'scipy'

